{"caseFolder":"normalTest//Try", "id":"9"}
{"jsonrpc":"2.0","id":"0","method":"initialize","params":{"processId":null,"rootPath":"C:/Users/code_project/DevEcoStudioProjects/MyApplication3","rootUri":"file:///c%3A/Users/code_project/DevEcoStudioProjects/MyApplication3/","capabilities":{"workspace":{"applyEdit":true,"workspaceEdit":{},"didChangeWatchedFiles":{},"symbol":{},"executeCommand":{},"workspaceFolders":false,"configuration":false},"textDocument":{"synchronization":{"willSave":true,"willSaveWaitUntil":true,"didSave":true},"completion":{"completionItem":{"snippetSupport":true}},"hover":{},"signatureHelp":{},"references":{},"documentHighlight":{"dynamicRegistration":true},"formatting":{},"rangeFormatting":{},"onTypeFormatting":{},"definition":{},"codeAction":{},"documentLink":{},"rename":{"prepareSupport":true},"semanticHighlightingCapabilities":{"semanticHighlighting":true},"callHierarchy":{},"semanticTokens":{"tokenTypes":["namespace","type","class","enum","interface","struct","typeParameter","parameter","variable","property","enumMember","event","function","method","macro","keyword","modifier","comment","string","number","regexp","operator","member","label"],"tokenModifiers":["declaration","definition","readonly","static","deprecated","abstract","async","modification","documentation","defaultLibrary"],"dynamicRegistration":true}}}}}
{"jsonrpc":"2.0","method":"initialized","params":{}}
{"jsonrpc":"2.0","method":"textDocument/didOpen","params":{"textDocument":{"uri":"file:///d:/test_char/src/Try.cj","languageId":"Cangjie","version":0,"text":"// Copyright (c) Huawei Technologies Co., Ltd. 2025. All rights reserved.\n// This source file is part of the Cangjie project, licensed under Apache-2.0\n// with Runtime Library Exception.\n//\n// See https://cangjie-lang.cn/pages/LICENSE for license information.\n\nfunc tesst() {\n    // Catch with wildcardPattern.\n    let a = 10\n    try {\n        a = 10\n    } catch (_) {\n        print(\"catch an exception!\")\n    }\n}\n\n\n// The first situation.\nfunc main1() {\n    try {\n        throw ArithmeticException()\n    } catch (e: RuntimeException) { // Caught.\n        print(\"RuntimeException and its subtypes can be caught here\")\n    }\n}\n\n// User defined exceptions.\nopen class Father <: Exception {\n    var father: Int32 = 0\n    func whatFather() { print(\"I am Father\") }\n}\nclass ChildOne <: Father {\n    var childOne: Int32 = 1\n    func whatChildOne() { print(\"I am ChildOne\") }\n    func whatChild() { print(\"I am method in ChildOne\") }\n}\nclass ChildTwo <: Father {\n    var childTwo: Int32 = 2\n    func whatChildTwo() { print(\"I am ChildTwo\") }\n    func whatChild() { print(\"I am method in ChildTwo\") }\n}\n\n// Function main.\nfunc main2() {\n    var a = 1\n    try {\n        a = 2\n    } catch (e: ChildOne | ChildTwo ){\n        e.whatFather() // ok: e is an object of Father\n        //e.whatChildOne() // error: e is an object of Father\n        //e.whatChild() // error: e is an object of Father\n        print(\"${e}\") // ok: e is an object of Father\n        //print(e.childOne) // error: e is an object of Father\n        //print(e.childOTwo) // error: e is an object of Father\n    }\n    func throwE() {\n        if (a == 1) {\n            throw ChildOne()\n        } else {\n            throw ChildTwo()\n        }\n    }\n    return 0\n}\n\nfunc f():Int64 {\n    var x = 1;\n    try {\n        return x + x;  // Return 2.\n    } catch (e: RuntimeException) { // Caught.\n        print(\"RuntimeException and its subtypes can be caught here\")\n    } finally {\n        x = 2;\n  }  // The return value is 2 but not 4.\n  return x;\n}\n\nfunc f11():Int64 {\n    var x = 1;\n    try {\n        return x + x;  // Return 2.\n    } catch (e: RuntimeException) { // Caught.\n        print(\"RuntimeException and its subtypes can be caught here\")\n    } finally {\n        x = 2;\n  }  // The return value is 2 but not 4.\n  return x;\n}\n\n\n// Caught by catchE().\nfunc catchE() {\n    let arrayTest: RefArray<Int32> = RefArray<Int32>([0, 1, 2])\n    try {\n        throwE() // caught by catchE()\n    } catch (e: Exception) {\n        print(\"an ArrayIndexOutOfBoundsException happened: \" )\n    }\n}\n\n// Terminate function is executed.\nfunc notCatchE() {\n    let arrayTest: RefArray<Int32> = RefArray<Int32>([0, 1, 2])\n    throwE()\n}\n\n// func throwE()\nfunc throwE() {}\nfunc throwE1() {throw Exception()}\n\nfunc a3() {\n    var a = 10\n    try {\n        throw Exception()\n        a = 10\n    }\n}//err\n\nfunc a2() {\n\n// Catch with exceptionTypePattern.\n    var a = 10\n\n    try {\n        throw Exception()\n        a = 10\n        try{\n            a = 10\n        }\n    } catch (e:  Exception) {\n        var b = 10\n    } finally {\n        print(\"the finally block is executed\")\n    }\n}\n"}}}
{"jsonrpc":"2.0","id":"4","method":"shutdown","params":{}}
{"jsonrpc":"2.0","method":"exit","params":{}}